{
 "cells": [
  {
   "cell_type": "code",
   "execution_count": 5,
   "id": "b8f46730-3571-4214-b1c7-4e10abdd0bcd",
   "metadata": {},
   "outputs": [],
   "source": [
    "import pandas as pd\n",
    "import csv\n"
   ]
  },
  {
   "cell_type": "code",
   "execution_count": 6,
   "id": "401b6022-c2b8-49f2-9151-d3837960f533",
   "metadata": {},
   "outputs": [
    {
     "name": "stdout",
     "output_type": "stream",
     "text": [
      "Unexpected exception formatting exception. Falling back to standard exception\n"
     ]
    },
    {
     "name": "stderr",
     "output_type": "stream",
     "text": [
      "Traceback (most recent call last):\n",
      "  File \"C:\\PythonInstall\\Lib\\site-packages\\IPython\\core\\interactiveshell.py\", line 3508, in run_code\n",
      "    exec(code_obj, self.user_global_ns, self.user_ns)\n",
      "  File \"C:\\Users\\Name\\AppData\\Local\\Temp\\ipykernel_26864\\1354727042.py\", line 3, in <module>\n",
      "    senator_csv = pd.read_csv(csv_file)\n",
      "                  ^^^^^^^^^^^^^^^^^^^^^\n",
      "  File \"C:\\Users\\Name\\AppData\\Roaming\\Python\\Python311\\site-packages\\pandas\\util\\_decorators.py\", line 211, in wrapper\n",
      "    return func(*args, **kwargs)\n",
      "           ^^^^^^^^^^^^^^^^^^^^^\n",
      "  File \"C:\\Users\\Name\\AppData\\Roaming\\Python\\Python311\\site-packages\\pandas\\util\\_decorators.py\", line 331, in wrapper\n",
      "    return func(*args, **kwargs)\n",
      "           ^^^^^^^^^^^^^^^^^^^^^\n",
      "  File \"C:\\Users\\Name\\AppData\\Roaming\\Python\\Python311\\site-packages\\pandas\\io\\parsers\\readers.py\", line 950, in read_csv\n",
      "    return _read(filepath_or_buffer, kwds)\n",
      "           ^^^^^^^^^^^^^^^^^^^^^^^^^^^^^^^\n",
      "  File \"C:\\Users\\Name\\AppData\\Roaming\\Python\\Python311\\site-packages\\pandas\\io\\parsers\\readers.py\", line 605, in _read\n",
      "    parser = TextFileReader(filepath_or_buffer, **kwds)\n",
      "             ^^^^^^^^^^^^^^^^^^^^^^^^^^^^^^^^^^^^^^^^^^\n",
      "  File \"C:\\Users\\Name\\AppData\\Roaming\\Python\\Python311\\site-packages\\pandas\\io\\parsers\\readers.py\", line 1442, in __init__\n",
      "    self._engine = self._make_engine(f, self.engine)\n",
      "                   ^^^^^^^^^^^^^^^^^^^^^^^^^^^^^^^^^\n",
      "  File \"C:\\Users\\Name\\AppData\\Roaming\\Python\\Python311\\site-packages\\pandas\\io\\parsers\\readers.py\", line 1735, in _make_engine\n",
      "    self.handles = get_handle(\n",
      "                   ^^^^^^^^^^^\n",
      "  File \"C:\\Users\\Name\\AppData\\Roaming\\Python\\Python311\\site-packages\\pandas\\io\\common.py\", line 856, in get_handle\n",
      "    handle = open(\n",
      "             ^^^^^\n",
      "FileNotFoundError: [Errno 2] No such file or directory: 'all_transactions.csv'\n",
      "\n",
      "During handling of the above exception, another exception occurred:\n",
      "\n",
      "Traceback (most recent call last):\n",
      "  File \"C:\\PythonInstall\\Lib\\site-packages\\IPython\\core\\interactiveshell.py\", line 2105, in showtraceback\n",
      "    stb = self.InteractiveTB.structured_traceback(\n",
      "          ^^^^^^^^^^^^^^^^^^^^^^^^^^^^^^^^^^^^^^^^\n",
      "  File \"C:\\PythonInstall\\Lib\\site-packages\\IPython\\core\\ultratb.py\", line 1428, in structured_traceback\n",
      "    return FormattedTB.structured_traceback(\n",
      "           ^^^^^^^^^^^^^^^^^^^^^^^^^^^^^^^^^\n",
      "  File \"C:\\PythonInstall\\Lib\\site-packages\\IPython\\core\\ultratb.py\", line 1319, in structured_traceback\n",
      "    return VerboseTB.structured_traceback(\n",
      "           ^^^^^^^^^^^^^^^^^^^^^^^^^^^^^^^\n",
      "  File \"C:\\PythonInstall\\Lib\\site-packages\\IPython\\core\\ultratb.py\", line 1172, in structured_traceback\n",
      "    formatted_exception = self.format_exception_as_a_whole(etype, evalue, etb, number_of_lines_of_context,\n",
      "                          ^^^^^^^^^^^^^^^^^^^^^^^^^^^^^^^^^^^^^^^^^^^^^^^^^^^^^^^^^^^^^^^^^^^^^^^^^^^^^^^^\n",
      "  File \"C:\\PythonInstall\\Lib\\site-packages\\IPython\\core\\ultratb.py\", line 1087, in format_exception_as_a_whole\n",
      "    frames.append(self.format_record(record))\n",
      "                  ^^^^^^^^^^^^^^^^^^^^^^^^^^\n",
      "  File \"C:\\PythonInstall\\Lib\\site-packages\\IPython\\core\\ultratb.py\", line 969, in format_record\n",
      "    frame_info.lines, Colors, self.has_colors, lvals\n",
      "    ^^^^^^^^^^^^^^^^\n",
      "  File \"C:\\PythonInstall\\Lib\\site-packages\\IPython\\core\\ultratb.py\", line 792, in lines\n",
      "    return self._sd.lines\n",
      "           ^^^^^^^^^^^^^^\n",
      "  File \"C:\\PythonInstall\\Lib\\site-packages\\stack_data\\utils.py\", line 144, in cached_property_wrapper\n",
      "    value = obj.__dict__[self.func.__name__] = self.func(obj)\n",
      "                                               ^^^^^^^^^^^^^^\n",
      "  File \"C:\\PythonInstall\\Lib\\site-packages\\stack_data\\core.py\", line 734, in lines\n",
      "    pieces = self.included_pieces\n",
      "             ^^^^^^^^^^^^^^^^^^^^\n",
      "  File \"C:\\PythonInstall\\Lib\\site-packages\\stack_data\\utils.py\", line 144, in cached_property_wrapper\n",
      "    value = obj.__dict__[self.func.__name__] = self.func(obj)\n",
      "                                               ^^^^^^^^^^^^^^\n",
      "  File \"C:\\PythonInstall\\Lib\\site-packages\\stack_data\\core.py\", line 677, in included_pieces\n",
      "    scope_pieces = self.scope_pieces\n",
      "                   ^^^^^^^^^^^^^^^^^\n",
      "  File \"C:\\PythonInstall\\Lib\\site-packages\\stack_data\\utils.py\", line 144, in cached_property_wrapper\n",
      "    value = obj.__dict__[self.func.__name__] = self.func(obj)\n",
      "                                               ^^^^^^^^^^^^^^\n",
      "  File \"C:\\PythonInstall\\Lib\\site-packages\\stack_data\\core.py\", line 614, in scope_pieces\n",
      "    scope_start, scope_end = self.source.line_range(self.scope)\n",
      "                             ^^^^^^^^^^^^^^^^^^^^^^^^^^^^^^^^^^\n",
      "  File \"C:\\PythonInstall\\Lib\\site-packages\\stack_data\\core.py\", line 178, in line_range\n",
      "    return line_range(self.asttext(), node)\n",
      "                      ^^^^^^^^^^^^^^\n",
      "  File \"C:\\PythonInstall\\Lib\\site-packages\\executing\\executing.py\", line 428, in asttext\n",
      "    self._asttext = ASTText(self.text, tree=self.tree, filename=self.filename)\n",
      "                    ^^^^^^^^^^^^^^^^^^^^^^^^^^^^^^^^^^^^^^^^^^^^^^^^^^^^^^^^^^\n",
      "  File \"C:\\PythonInstall\\Lib\\site-packages\\asttokens\\asttokens.py\", line 307, in __init__\n",
      "    super(ASTText, self).__init__(source_text, filename)\n",
      "  File \"C:\\PythonInstall\\Lib\\site-packages\\asttokens\\asttokens.py\", line 44, in __init__\n",
      "    source_text = six.ensure_text(source_text)\n",
      "                  ^^^^^^^^^^^^^^^\n",
      "AttributeError: module 'six' has no attribute 'ensure_text'\n"
     ]
    }
   ],
   "source": [
    "csv_file = (\"all_transactions.csv\")\n",
    "\n",
    "senator_csv = pd.read_csv(csv_file)\n",
    "\n",
    "senator_csv.head()"
   ]
  },
  {
   "cell_type": "code",
   "execution_count": null,
   "id": "1db4c864-8ce1-4dc7-ae40-3dce81a74b54",
   "metadata": {},
   "outputs": [],
   "source": []
  }
 ],
 "metadata": {
  "kernelspec": {
   "display_name": "Python 3 (ipykernel)",
   "language": "python",
   "name": "python3"
  },
  "language_info": {
   "codemirror_mode": {
    "name": "ipython",
    "version": 3
   },
   "file_extension": ".py",
   "mimetype": "text/x-python",
   "name": "python",
   "nbconvert_exporter": "python",
   "pygments_lexer": "ipython3",
   "version": "3.9.17"
  }
 },
 "nbformat": 4,
 "nbformat_minor": 5
}
